<?xml version="1.0" ?>
<sdf version="1.6">
<!--Copyright 2016-2022 The FEAGI Authors. All Rights Reserved.-->

<!--Licensed under the Apache License, Version 2.0 (the "License");-->
<!--you may not use this file except in compliance with the License.-->
<!--You may obtain a copy of the License at-->

<!--    http://www.apache.org/licenses/LICENSE-2.0-->

<!--Unless required by applicable law or agreed to in writing, software-->
<!--distributed under the License is distributed on an "AS IS" BASIS,-->
<!--WITHOUT WARRANTIES OR CONDITIONS OF ANY KIND, either express or implied.-->
<!--See the License for the specific language governing permissions and-->
<!--limitations under the License.-->
<!--==============================================================================-->
    <model name='smart_car'>
      <pose>0 4.12 0.325 0 -0 0</pose>
    <!--     BODY PARTS        -->
        <link name='chassis'>
            <pose>0 0 .1 0 0 0</pose>
            <inertial>
              <mass>40</mass>
              <inertia>
                <ixx>0.005</ixx>
                <ixy>0</ixy>
                <ixz>0</ixz>
                <iyy>0.005</iyy>
                <iyz>0</iyz>
                <izz>0.005</izz>
              </inertia>
            </inertial>
            <visual name='visual'>
              <geometry>
                <box>
                  <size>0.2159 0.1524 0.10795</size>
                </box>
              </geometry>
              <material>
                <ambient>0.5 1.0 0.5 1</ambient>
                <diffuse>0.5 1.0 0.5 1</diffuse>
                <specular>0.0 1.0 0.0 1</specular>
              </material>
            </visual>
            <collision name='collision'>
              <geometry>
                <box>
                  <size>0.2159 0.1524 0.10795</size>
                </box>
              </geometry>
            </collision>
              <sensor name="imu" type="imu">
              <always_on>1</always_on>
              <update_rate>100</update_rate>
              <visualize>true</visualize>
              <topic>imu</topic>
              <enable_metrics>true</enable_metrics>
            </sensor>
          </link>

        <link name='rod_one'>
            <pose>0.160 0 0.045 0 -1.6 0</pose>
            <visual name='visual'>
              <geometry>
                <cylinder>
                  <radius>0.005</radius>
                  <length>.1</length>
                </cylinder>
              </geometry>
              <material>
                <ambient>0.8 0.0 0.5 0.0</ambient>
                <diffuse>0.5 0.0 0.5 1</diffuse>
                <specular>0.2 0.3 0.4 0.5</specular>
              </material>
            </visual>
          </link>

        <link name='second_rod'>
            <pose relative_to='rod_one'>0 0 -0.05 -1.6 -1.6 0</pose>
            <visual name='visual'>
              <geometry>
                <cylinder>
                  <radius>0.005</radius>
                  <length>.2</length>
                </cylinder>
              </geometry>
              <material>
                <ambient>0.8 0.0 0.5 0.0</ambient>
                <diffuse>0.5 0.0 0.5 1</diffuse>
                <specular>0.2 0.3 0.4 0.5</specular>
              </material>
            </visual>
          </link>



    <!--        Wheel section   -->

      <link name='rear_left_wheel'>
        <pose>-0.1 0.088 0.05 0 1.5707 1.5707</pose>
      <mass>20</mass>
        <inertial>
        <inertia>
          <ixx>0.0264</ixx>
          <iyy>0.0264</iyy>
          <izz>0.0211</izz>
          <ixy>0</ixy>
          <ixz>0</ixz>
          <iyz>0</iyz>
        </inertia>
      </inertial>
        <visual name='visual'>
          <geometry>
            <cylinder>
              <radius>0.0325</radius>
              <length>.02</length>
            </cylinder>
          </geometry>
          <material>
            <ambient>0.2 0.2 0.2 1</ambient>
            <diffuse>0.2 0.2 0.2 1</diffuse>
            <specular>0.2 0.2 0.2 1</specular>
            <pbr>
                <metal>
                  <albedo_map>material/wheel_cover.png</albedo_map>
                  <normal_map>material/wheel_cover.png</normal_map>
                </metal>
            </pbr>
          </material>
        </visual>
        <collision name='collision'>
          <geometry>
            <cylinder>
              <radius>0.0325</radius>
              <length>.02</length>
            </cylinder>
          </geometry>
          <surface>
            <friction>
            <ode>
              <mu>0.9</mu>
              <mu2>1</mu2>
              <fdir1>1 1 0</fdir1>
              <slip1>0.1</slip1>
              <slip2>0.1</slip2>
            </ode>
            </friction>
          </surface>
        </collision>
      </link>

      <link name='rear_right_wheel'>
        <pose> -0.1 -0.088 0.05 0 1.5707 1.5707 </pose>
      <mass>20</mass>
        <inertial>
        <inertia>
          <ixx>0.0264</ixx>
          <iyy>0.0264</iyy>
          <izz>0.0211</izz>
          <ixy>0</ixy>
          <ixz>0</ixz>
          <iyz>0</iyz>
        </inertia>
      </inertial>
        <visual name='visual'>
          <geometry>
            <cylinder>
              <radius>0.0325</radius>
              <length>.02</length>
            </cylinder>
          </geometry>
          <material>
            <ambient>0.2 0.2 0.2 1</ambient>
            <diffuse>0.2 0.2 0.2 1</diffuse>
            <specular>0.2 0.2 0.2 1</specular>
            <pbr>
                <metal>
                  <albedo_map>material/wheel_cover.png</albedo_map>
                  <normal_map>material/wheel_cover.png</normal_map>
                </metal>
            </pbr>
          </material>
        </visual>
        <collision name='collision'>
          <geometry>
            <cylinder>
              <radius>0.0325</radius>
              <length>.02</length>
            </cylinder>
          </geometry>
          <surface>
            <friction>
            <ode>
              <mu>0.9</mu>
              <mu2>1</mu2>
              <fdir1>1 1 0</fdir1>
              <slip1>0.1</slip1>
              <slip2>0.1</slip2>
            </ode>
            </friction>
          </surface>
        </collision>
      </link>

      <link name='front_left_wheel'>
        <pose>0.1 0.088 0.05 0 1.5707 1.5707</pose>
      <mass>20</mass>
        <inertial>
        <inertia>
          <ixx>0.0264</ixx>
          <iyy>0.0264</iyy>
          <izz>0.0211</izz>
          <ixy>0</ixy>
          <ixz>0</ixz>
          <iyz>0</iyz>
        </inertia>
      </inertial>
        <visual name='visual'>
          <geometry>
            <cylinder>
              <radius>0.0325</radius>
              <length>.02</length>
            </cylinder>
          </geometry>
          <material>
            <ambient>0.2 0.2 0.2 1</ambient>
            <diffuse>0.2 0.2 0.2 1</diffuse>
            <specular>0.2 0.2 0.2 1</specular>
            <pbr>
                <metal>
                  <albedo_map>material/wheel_cover.png</albedo_map>
                  <normal_map>material/wheel_cover.png</normal_map>
                </metal>
            </pbr>
          </material>
        </visual>
        <collision name='collision'>
          <geometry>
            <cylinder>
              <radius>0.0325</radius>
              <length>.02</length>
            </cylinder>
          </geometry>
          <surface>
            <friction>
            <ode>
              <mu>0.9</mu>
              <mu2>1</mu2>
              <fdir1>1 1 0</fdir1>
              <slip1>0.1</slip1>
              <slip2>0.1</slip2>
            </ode>
            </friction>
          </surface>
        </collision>
      </link>

      <link name='front_right_wheel'>
        <pose>0.1 -0.088 0.05 0 1.5707 1.5707</pose>
      <mass>20</mass>
        <inertial>
        <inertia>
          <ixx>0.0264</ixx>
          <iyy>0.0264</iyy>
          <izz>0.0211</izz>
          <ixy>0</ixy>
          <ixz>0</ixz>
          <iyz>0</iyz>
        </inertia>
      </inertial>
        <visual name='visual'>
          <geometry>
             <cylinder>
              <radius>0.0325</radius>
              <length>.02</length>
            </cylinder>
          </geometry>
          <material>
            <ambient>0.2 0.2 0.2 1</ambient>
            <diffuse>0.2 0.2 0.2 1</diffuse>
            <specular>0.2 0.2 0.2 1</specular>
            <pbr>
                <metal>
                  <albedo_map>material/wheel_cover.png</albedo_map>
                  <normal_map>material/wheel_cover.png</normal_map>
                </metal>
            </pbr>
          </material>
        </visual>
        <collision name='collision'>
          <geometry>
            <cylinder>
              <radius>0.0325</radius>
              <length>.02</length>
            </cylinder>
          </geometry>
          <surface>
            <friction>
            <ode>
              <mu>0.9</mu>
              <mu2>1</mu2>
              <fdir1>1 1 0</fdir1>
              <slip1>0.1</slip1>
              <slip2>0.1</slip2>
            </ode>
            </friction>
          </surface>
        </collision>
      </link>


    <!--        Servo section   -->

      <link name='head'>
        <pose>0.090 0 0.16 0 0 0</pose>
        <inertial>
        <mass>0.06442</mass>
        <inertia>
          <ixx>7.4993e-05</ixx>
          <ixy>1.57e-09</ixy>
          <ixz>-1.834e-08</ixz>
          <iyy>7.6e-05</iyy>
          <iyz>-5.295e-08</iyz>
          <izz>5.53373e-06</izz>
        </inertia>
        </inertial>
        <visual name='visual'>
          <geometry>
          <cylinder>
            <radius>0.01</radius>
            <length>0.02</length>
          </cylinder>
          </geometry>
          <material>
            <ambient>0.2 0.2 0.2 1</ambient>
            <diffuse>0.2 0.2 0.2 1</diffuse>
            <specular>0.2 0.2 0.2 1</specular>
          </material>
        </visual>
      <gravity>1</gravity>
      <velocity_decay/>
      <self_collide>0</self_collide>
        <collision name='collision'>
          <geometry>
          <cylinder>
            <radius>0.01</radius>
            <length>0.02</length>
          </cylinder>
          </geometry>
        </collision>
      </link>

      <link name='head2'>
        <pose>0.090 0 0.18 0 0 -1.6</pose>
        <inertial>
          <mass>0.03</mass>
          <inertia>
            <ixx>0.001</ixx>
            <ixy>0</ixy>
            <ixz>0</ixz>
            <iyy>0.001</iyy>
            <iyz>0</iyz>
            <izz>0.001</izz>
          </inertia>
        </inertial>
        <visual name='visual'>
          <geometry>
          <cylinder>
            <radius>0.01</radius>
            <length>0.02</length>
          </cylinder>
          </geometry>
          <material>
            <ambient>0.2 0.2 0.2 1</ambient>
            <diffuse>0.2 0.2 0.2 1</diffuse>
            <specular>0.2 0.2 0.2 1</specular>
          </material>
        </visual>
        <collision name='collision'>
          <geometry>
          <cylinder>
            <radius>0.01</radius>
            <length>0.02</length>
          </cylinder>
          </geometry>
        </collision>
      </link>

    <!--    sensor section   -->

      <link name='sensor'>
      <pose relative_to='head2'>0 0 0.0201 0 -1.55 0</pose>
<!--      <pose>0.11 0 0.18 0 0 0</pose>-->
     <inertial>
          <mass>0.02</mass>
          <inertia>
            <ixx>0.001</ixx>
            <ixy>0</ixy>
            <ixz>0</ixz>
            <iyy>0.001</iyy>
            <iyz>0</iyz>
            <izz>0.001</izz>
          </inertia>
        </inertial>
      <visual name='visual'>
        <pose>0 0 0 0 0 0</pose>
        <geometry>
          <box>
            <size>0.02 0.04 0.01</size>
          </box>
        </geometry>
      </visual>
    <collision name="collision">
        <pose >0 0 0 0 0 0</pose>
        <geometry>
          <box>
            <size>0.02 0.04 0.01</size>
          </box>
        </geometry>
      </collision>
      <frame name="lidar_frame" attached_to='sensor'>
        </frame>
      <sensor name='gpu_lidar' type='gpu_lidar'>
          <always_on>1</always_on>
          <visualize>true</visualize>
          <topic>ultrasonic0</topic>
          <update_rate>100</update_rate>
          <lidar>
              <scan>
                  <vertical>
                    <samples>5</samples>
                    <resolution>1</resolution>
                    <min_angle>0.00</min_angle>
                    <max_angle>0.25</max_angle>
                  </vertical>
              </scan>
          <range>
            <min>0.120000</min>
            <max>4</max>
            <resolution>0.015000</resolution>
          </range>
          <noise>
            <type>gaussian</type>
            <mean>0.0</mean>
            <stddev>0.01</stddev>
          </noise>
        </lidar>
    </sensor>
      <sensor name="rgbd_camera" type="rgbd_camera">
          <update_rate>100</update_rate>
          <visualize>true</visualize>
          <always_on>1</always_on>
          <topic>Camera0</topic>
          <camera>
<!--            <horizontal_fov>0.1</horizontal_fov>-->
            <image>
              <width>600</width>
              <height>600</height>
              <format>L_INT8</format>
<!--              <anti-aliasing>1</anti-aliasing>-->
            </image>
            <clip>
              <near>0.1</near>
              <far>10</far>
            </clip>
            <scale_to_hfov>true</scale_to_hfov>
          </camera>
      </sensor>
    </link>

      <link name='right_IR'>
<!--        <pose relative_to='second_rod'>-0.014 0 -0.04 1.6 0 -1.3</pose>-->
      <pose>0.215 0.090 0.042 0 1.6 0</pose>
     <inertial>
          <mass>0.01</mass>
          <inertia>
            <ixx>0.126164</ixx>
            <ixy>0</ixy>
            <ixz>0</ixz>
            <iyy>0.416519</iyy>
            <iyz>0</iyz>
            <izz>0.481014</izz>
          </inertia>
        </inertial>
      <visual name='visual'>
        <pose>0 0 0 0 0 0</pose>
        <geometry>
          <box>
            <size>0.001 0.004 0.001</size>
          </box>
        </geometry>
        <material>
            <ambient>1 0 0 1</ambient>
            <diffuse>1 0 0 1</diffuse>
            <specular>0.1 0.1 0.1 1</specular>
            <emissive>0 0 0 0</emissive>
      </material>
      </visual>
      <sensor name="rgbd_camera" type="rgbd_camera">
          <update_rate>100</update_rate>
          <visualize>true</visualize>
          <always_on>1</always_on>
          <topic>IR0</topic>
          <camera>
            <horizontal_fov>0.1</horizontal_fov>
            <image>
              <width>1</width>
              <height>1</height>
              <format>L_INT8</format>
              <anti-aliasing>1</anti-aliasing>
            </image>
            <clip>
              <near>0.02</near>
              <far>10.0</far>
            </clip>
          </camera>
      </sensor>
    </link>

      <link name='left_IR'>
<!--        <pose relative_to='second_rod'>-0.014 0 0.04 1.6 0 -1.3</pose>-->
      <pose>0.215 -0.090 0.042 0 1.6 0</pose>
     <inertial>
          <mass>0.01</mass>
          <inertia>
            <ixx>0.126164</ixx>
            <ixy>0</ixy>
            <ixz>0</ixz>
            <iyy>0.416519</iyy>
            <iyz>0</iyz>
            <izz>0.481014</izz>
          </inertia>
        </inertial>
      <visual name='visual'>
        <pose>0 0 0 0 0 0</pose>
        <geometry>
          <box>
            <size>0.001 0.004 0.001</size>
          </box>
        </geometry>
        <material>
            <ambient>1 0 0 1</ambient>
            <diffuse>1 0 0 1</diffuse>
            <specular>0.1 0.1 0.1 1</specular>
            <emissive>0 0 0 0</emissive>
      </material>
      </visual>
        <sensor name="rgbd_camera" type="rgbd_camera">
          <update_rate>100</update_rate>
          <topic>IR2</topic>
          <camera>
            <horizontal_fov>0.1</horizontal_fov>
            <image>
              <width>1</width>
              <height>1</height>
              <format>L_INT8</format>
              <anti-aliasing>1</anti-aliasing>
            </image>
            <clip>
              <near>0.02</near>
              <far>10.0</far>
            </clip>
          </camera>
        </sensor>
    </link>

      <link name='middle_IR'>
<!--        <pose relative_to='second_rod'>-0.014 0 0 1.6 0 -1.3</pose>-->
      <pose>0.215 0 0.042 0 1.6 0</pose>
     <inertial>
          <mass>0.01</mass>
          <inertia>
            <ixx>0.126164</ixx>
            <ixy>0</ixy>
            <ixz>0</ixz>
            <iyy>0.416519</iyy>
            <iyz>0</iyz>
            <izz>0.481014</izz>
          </inertia>
        </inertial>
      <visual name='visual'>
        <pose>0 0 0 0 0 0</pose>
        <geometry>
          <box>
            <size>0.001 0.004 0.001</size>
          </box>
        </geometry>
        <material>
            <ambient>1 0 0 1</ambient>
            <diffuse>1 0 0 1</diffuse>
            <specular>0.1 0.1 0.1 1</specular>
            <emissive>0 0 0 0</emissive>
      </material>
      </visual>
      <sensor name="rgbd_camera" type="rgbd_camera">
          <update_rate>100</update_rate>
          <topic>IR1</topic>
          <camera>
            <horizontal_fov>0.1</horizontal_fov>
            <image>
              <width>1</width>
              <height>1</height>
              <format>L_INT8</format>
              <anti-aliasing>1</anti-aliasing>
            </image>
            <clip>
              <near>0.02</near>
              <far>10.0</far>
            </clip>
          </camera>
      </sensor>
    </link>


    <!--        Joint section        -->

    <joint name='rear_left_wheel_joint' type='revolute'>
        <parent>chassis</parent>
        <child>rear_left_wheel</child>
        <axis>
          <xyz>0 1 0</xyz>
        <limit>
            <lower>-1.79769e+308</lower>    <!--negative infinity-->
            <upper>1.79769e+308</upper>     <!--positive infinity-->
        </limit>
        <dynamics>
          <damping>1</damping>
          <friction>1</friction>
          <spring_reference>0</spring_reference>
          <spring_stiffness>0</spring_stiffness>
        </dynamics>
        <use_parent_model_frame>1</use_parent_model_frame>
        </axis>
      <physics>
        <ode>
          <implicit_spring_damper>1</implicit_spring_damper>
          <cfm_damping>1</cfm_damping>
          <limit>
            <cfm>0</cfm>
            <erp>0.2</erp>
          </limit>
        </ode>
      </physics>
      </joint>
      <!--      M2 topic-->
    <plugin
          filename="ignition-gazebo-joint-position-controller-system"
          name="ignition::gazebo::systems::JointPositionController">
          <joint_name>rear_left_wheel_joint</joint_name>
                <topic>M2</topic>
    </plugin>


    <joint name='rear_right_wheel_joint' type='revolute'>
        <parent>chassis</parent>
        <child>rear_right_wheel</child>
        <axis>
          <xyz>0 1 0</xyz>
        <limit>
            <lower>-1.79769e+308</lower>    <!--negative infinity-->
            <upper>1.79769e+308</upper>     <!--positive infinity-->
        </limit>
        <dynamics>
          <damping>1</damping>
          <friction>1</friction>
          <spring_reference>0</spring_reference>
          <spring_stiffness>0</spring_stiffness>
        </dynamics>
        <use_parent_model_frame>1</use_parent_model_frame>
        </axis>
      <physics>
        <ode>
          <implicit_spring_damper>1</implicit_spring_damper>
          <cfm_damping>1</cfm_damping>
          <limit>
            <cfm>0</cfm>
            <erp>0.2</erp>
          </limit>
        </ode>
      </physics>
      </joint>
      <!--      M3 topic-->
    <plugin
          filename="ignition-gazebo-joint-position-controller-system"
          name="ignition::gazebo::systems::JointPositionController">
          <joint_name>rear_right_wheel_joint</joint_name>
                <topic>M3</topic>
    </plugin>



    <joint name='front_left_wheel_joint' type='revolute'>
        <parent>chassis</parent>
        <child>front_left_wheel</child>
        <axis>
          <xyz>0 1 0</xyz>
        <limit>
            <lower>-1.79769e+308</lower>    <!--negative infinity-->
            <upper>1.79769e+308</upper>     <!--positive infinity-->
        </limit>
        <dynamics>
          <damping>1</damping>
          <friction>1</friction>
          <spring_reference>0</spring_reference>
          <spring_stiffness>0</spring_stiffness>
        </dynamics>
        <use_parent_model_frame>1</use_parent_model_frame>
        </axis>
      <physics>
        <ode>
          <implicit_spring_damper>1</implicit_spring_damper>
          <cfm_damping>1</cfm_damping>
          <limit>
            <cfm>0</cfm>
            <erp>0.2</erp>
          </limit>
        </ode>
      </physics>
      </joint>
      <!--      M0 topic-->
    <plugin
          filename="ignition-gazebo-joint-position-controller-system"
          name="ignition::gazebo::systems::JointPositionController">
          <joint_name>front_left_wheel_joint</joint_name>
                <topic>M0</topic>
    </plugin>


    <joint name='front_right_wheel_joint' type='revolute'>
        <parent>chassis</parent>
        <child>front_right_wheel</child>
        <axis>
          <xyz>0 1 0</xyz>
        <limit>
            <lower>-1.79769e+308</lower>    <!--negative infinity-->
            <upper>1.79769e+308</upper>     <!--positive infinity-->
        </limit>
        <dynamics>
          <damping>1</damping>
          <friction>1</friction>
          <spring_reference>0</spring_reference>
          <spring_stiffness>0</spring_stiffness>
        </dynamics>
        <use_parent_model_frame>1</use_parent_model_frame>
        </axis>
      <physics>
        <ode>
          <implicit_spring_damper>1</implicit_spring_damper>
          <cfm_damping>1</cfm_damping>
          <limit>
            <cfm>0</cfm>
            <erp>0.2</erp>
          </limit>
        </ode>
      </physics>
      </joint>
      <!--      M1 topic-->
    <plugin
          filename="ignition-gazebo-joint-position-controller-system"
          name="ignition::gazebo::systems::JointPositionController">
          <joint_name>front_right_wheel_joint</joint_name>
                <topic>M1</topic>
    </plugin>


    <joint name='ultrasonic' type='fixed'>
        <parent>head2</parent>
        <child>sensor</child>
      </joint>

    <joint name='head_attach' type='revolute'>
        <parent>chassis</parent>
        <child>head</child>
        <axis>
          <xyz>0 0 1</xyz>
          <limit>
            <lower>0.1</lower>
            <upper>3.1</upper>
          </limit>
          <dynamics>
          <damping>1</damping>
          <friction>0</friction>
          <spring_reference>0</spring_reference>
          <spring_stiffness>0</spring_stiffness>
        </dynamics>
        <use_parent_model_frame>1</use_parent_model_frame>
        </axis>
      <physics>
        <ode>
          <implicit_spring_damper>1</implicit_spring_damper>
          <cfm_damping>1</cfm_damping>
          <limit>
            <cfm>0</cfm>
            <erp>0.2</erp>
          </limit>
        </ode>
      </physics>
      </joint>
            <!--      S0 topic-->
    <plugin
          filename="ignition-gazebo-joint-position-controller-system"
          name="ignition::gazebo::systems::JointPositionController">
          <joint_name>head_attach</joint_name>
                <topic>S0</topic>
                <p_gain>10</p_gain>
                <i_gain>0.1</i_gain>
                <d_gain>0.01</d_gain>
                <i_max>1</i_max>
                <i_min>-1</i_min>
                <cmd_max>1000</cmd_max>
                <cmd_min>-1000</cmd_min>
    </plugin>


    <joint name='head_attach2' type='revolute'>
    <parent>head</parent>
    <child>head2</child>
    <axis>
      <xyz>1 0 0</xyz>
      <limit>
        <lower>-0.2</lower>
        <upper>1.6</upper>
      </limit>
          <dynamics>
          <damping>1</damping>
          <friction>0</friction>
          <spring_reference>0</spring_reference>
          <spring_stiffness>0</spring_stiffness>
        </dynamics>
        <use_parent_model_frame>1</use_parent_model_frame>
        </axis>
      <physics>
        <ode>
          <implicit_spring_damper>1</implicit_spring_damper>
          <cfm_damping>1</cfm_damping>
          <limit>
            <cfm>0</cfm>
            <erp>0.2</erp>
          </limit>
        </ode>
      </physics>
  </joint>
            <!--      S1 topic-->
      <plugin
          filename="ignition-gazebo-joint-position-controller-system"
          name="ignition::gazebo::systems::JointPositionController">
          <joint_name>head_attach2</joint_name>
                <topic>S1</topic>
                <p_gain>10</p_gain>
                <i_gain>0.1</i_gain>
                <d_gain>0.01</d_gain>
                <i_max>1</i_max>
                <i_min>-1</i_min>
                <cmd_max>1000</cmd_max>
                <cmd_min>-1000</cmd_min>
    </plugin>


  <joint name='rod1' type='fixed'>
    <parent>chassis</parent>
    <child>rod_one</child>
  </joint>

    <joint name='board' type='fixed'>
    <parent>rod_one</parent>
    <child>second_rod</child>
  </joint>

   <joint name='IR_right' type='fixed'>
    <parent>second_rod</parent>
    <child>right_IR</child>
  </joint>

   <joint name='IR_left' type='fixed'>
    <parent>second_rod</parent>
    <child>left_IR</child>
  </joint>

   <joint name='IR_middle' type='fixed'>
    <parent>second_rod</parent>
    <child>middle_IR</child>
  </joint>

    <plugin filename="ignition-gazebo-linearbatteryplugin-system"
        name="ignition::gazebo::systems::LinearBatteryPlugin">
        <!--Li-ion battery spec from LIR18650 datasheet-->
        <battery_name>linear_battery</battery_name>
        <voltage>8.40</voltage>
        <open_circuit_voltage_constant_coef>8.40</open_circuit_voltage_constant_coef>
        <open_circuit_voltage_linear_coef>-2.0</open_circuit_voltage_linear_coef>
        <initial_charge>2.5</initial_charge>
        <capacity>2.5</capacity>
        <resistance>0.07</resistance>
        <smooth_current_tau>2.0</smooth_current_tau>
        <enable_recharge>false</enable_recharge>
        <!-- charging I = c / t, discharging I = P / V,
          charging I should be > discharging I -->
<!--        <charging_time>3.0</charging_time>-->
<!--        <soc_threshold>0.51</soc_threshold>-->
        <!-- Consumer-specific -->
        <power_load>0.2</power_load>
        <start_on_motion>true</start_on_motion>
      </plugin>

  <plugin
      filename="ignition-gazebo-sensors-system"
      name="ignition::gazebo::systems::Sensors">
      <render_engine>ogre2</render_engine>
  </plugin>


  </model>

</sdf>
